<?xml version="1.0"?>
<robot xmlns:xacro="http://ros.org/wiki/xacro" name="uf_bio_gripper">
  <xacro:macro name="bio_gripper_urdf" params="prefix:='' attach_to:='' attach_xyz:='0 0 0' attach_rpy:='0 0 0' ">
    
    <xacro:unless value="${attach_to == ''}">
      <joint name="${prefix}bio_gripper_fix" type="fixed">
        <parent link="${attach_to}"/>
        <child link="${prefix}bio_gripper_base_link"/>
        <origin xyz="${attach_xyz}" rpy="${attach_rpy}"/>
      </joint>
    </xacro:unless>
    
    <link name="${prefix}bio_gripper_base_link">
      <inertial>
        <origin xyz="0.016179 -2.3911E-05 0.023897" rpy="0 0 0" />
        <mass value="0.38837" />
        <inertia
          ixx="0.00088398" ixy="4.8665E-08" ixz="5.6276E-06"
          iyy="0.00018256" iyz="4.0828E-08" izz="0.00094673" />
      </inertial>
      <xacro:common_link_visual 
        mesh_filename="gripper/bio/link_base"  
        origin_xyz="0 0 0" 
        origin_rpy="0 0 0"
        material_name="${prefix}White" />
      <xacro:common_link_collision 
        mesh_filename="gripper/bio/link_base"  
        origin_xyz="0 0 0" 
        origin_rpy="0 0 0" />
    </link>

    <link name="${prefix}bio_gripper_left_finger">
      <inertial>
        <origin xyz="0.021846 -0.0276 0.011911" rpy="0 0 0" />
        <mass value="0.012105" />
        <inertia
          ixx="3.7322E-06" ixy="4.1705E-06" ixz="-4.0142E-06"
          iyy="1.744E-05" iyz="1.2237E-06" izz="1.7775E-05" />
      </inertial>
      <xacro:common_link_visual 
        mesh_filename="gripper/bio/left_finger"  
        origin_xyz="0 0 0" 
        origin_rpy="0 0 0"
        material_name="${prefix}White" />
      <xacro:common_link_collision 
        mesh_filename="gripper/bio/left_finger"  
        origin_xyz="0 0 0" 
        origin_rpy="0 0 0" />
    </link>
    <joint name="${prefix}left_finger_joint" type="prismatic">
      <origin xyz="0.059 0 0.027" rpy="0 0 0" />
      <parent link="${prefix}bio_gripper_base_link" />
      <child link="${prefix}bio_gripper_left_finger" />
      <axis xyz="0 1 0" />
      <limit lower="-0.04" upper="0.0" effort="2.0" velocity="0.1" />
      <mimic joint="${prefix}right_finger_joint" multiplier="-1" offset="0" />
    </joint>

    <link name="${prefix}bio_gripper_right_finger">
      <inertial>
        <origin xyz="0.02037 0.027565 0.010274" rpy="0 0 0" />
        <mass value="0.012068" />
        <inertia
          ixx="4.1413E-06" ixy="-3.9682E-06" ixz="-4.5734E-06"
          iyy="1.6115E-05" iyz="-1.6711E-06" izz="1.6032E-05" />
      </inertial>
      <xacro:common_link_visual 
        mesh_filename="gripper/bio/right_finger"  
        origin_xyz="0 0 0" 
        origin_rpy="0 0 0"
        material_name="${prefix}White" />
      <xacro:common_link_collision 
        mesh_filename="gripper/bio/right_finger"  
        origin_xyz="0 0 0" 
        origin_rpy="0 0 0" />
    </link>
    <joint name="${prefix}right_finger_joint" type="prismatic">
      <origin xyz="0.059 0 0.027" rpy="0 0 0" />
      <parent link="${prefix}bio_gripper_base_link" />
      <child link="${prefix}bio_gripper_right_finger" />
      <axis xyz="0 1 0" />
      <limit lower="0" upper="0.04" effort="2.0" velocity="0.1" />
    </joint>
    

    <link name="${prefix}link_tcp" />

    <joint name="${prefix}joint_tcp" type="fixed">
      <origin xyz="0.135 0 0.055" rpy="0 0 0" />
      <parent link="${prefix}bio_gripper_base_link" />
      <child link="${prefix}link_tcp" />
    </joint>

  </xacro:macro>

</robot>