<?xml version="1.0"?>
<robot xmlns:xacro="http://ros.org/wiki/xacro">

<!--
  Author: Jimy Zhang <jimy.zhang@ufactory.cc> <jimy92@163.com>
  Contributers:
-->

  <xacro:macro name="xarm7_urdf" params="prefix
    joint1_lower_limit:=${-2.0*pi}  joint1_upper_limit:=${2.0*pi}
    joint2_lower_limit:=${-2.059}  joint2_upper_limit:=${2.0944}
    joint3_lower_limit:=${-2.0*pi}  joint3_upper_limit:=${2.0*pi}
    joint4_lower_limit:=${-0.19198}  joint4_upper_limit:=${3.927}
    joint5_lower_limit:=${-2.0*pi}  joint5_upper_limit:=${2.0*pi}
    joint6_lower_limit:=${-1.69297}  joint6_upper_limit:=${pi}
    joint7_lower_limit:=${-2.0*pi}  joint7_upper_limit:=${2.0*pi}
    rs_d435i:=false  model1300:=false">

    <material name="Black">
      <color rgba="0.0 0.0 0.0 1.0"/>
    </material>

    <material name="Red">
      <color rgba="0.8 0.0 0.0 1.0"/>
    </material>

    <material name="White">
      <color rgba="1.0 1.0 1.0 1.0"/>
    </material>

    <material name="Silver">
      <color rgba="0.753 0.753 0.753 1.0"/>
    </material>

    <link
    name="${prefix}link_base">
    <inertial>
      <origin
        xyz="-0.021131 -0.0016302 0.056488"
        rpy="0 0 0" />
      <mass
        value="2.612" />
      <inertia
        ixx="0.0030595"
        ixy="0.00012259"
        ixz="-0.00062705"
        iyy="0.0037783"
        iyz="0.00027023"
        izz="0.0020125" />
    </inertial>
    <visual>
      <origin
        xyz="0 0 0"
        rpy="0 0 0" />
      <geometry>
        <mesh
          filename="package://xarm_description/meshes/xarm7/visual/link_base.STL" />
      </geometry>
      <material name="White" />
    </visual>
    <collision>
      <origin
        xyz="0 0 0"
        rpy="0 0 0" />
      <geometry>
        <mesh
          filename="package://xarm_description/meshes/xarm7/visual/link_base.STL" />
      </geometry>
    </collision>
  </link>
  <link
    name="${prefix}link1">
    <inertial>
      <origin
        xyz="0.00013 0.0301 -0.012"
        rpy="0 0 0" />
      <mass
        value="2.459" />
      <inertia
        ixx="0.005795"
        ixy="-1.078E-05"
        ixz="-2.63E-05"
        iyy="0.004969"
        iyz="0.000911"
        izz="0.003428" />
    </inertial>
    <visual>
      <origin
        xyz="0 0 0"
        rpy="0 0 0" />
      <geometry>
        <mesh
          filename="package://xarm_description/meshes/xarm7/visual/link1.STL" />
      </geometry>
      <material name="White" />
    </visual>
    <collision>
      <origin
        xyz="0 0 0"
        rpy="0 0 0" />
      <geometry>
        <mesh
          filename="package://xarm_description/meshes/xarm7/visual/link1.STL" />
      </geometry>
    </collision>
  </link>
  <joint
    name="${prefix}joint1"
    type="revolute">
    <origin
      xyz="0 0 0.267"
      rpy="0 0 0" />
    <parent
      link="${prefix}link_base" />
    <child
      link="${prefix}link1" />
    <axis
      xyz="0 0 1" />
    <limit
      lower="${joint1_lower_limit}"
      upper="${joint1_upper_limit}"
      effort="50"
      velocity="3.14" />
    <dynamics
      damping="10"
      friction="1" />
  </joint>
  <link
    name="${prefix}link2">
    <inertial>
      <origin
        xyz="0.0002 -0.12964 0.01692"
        rpy="0 0 0" />
      <mass
        value="1.916" />
      <inertia
        ixx="0.0097184"
        ixy="1.0E-06"
        ixz="-4.83E-06"
        iyy="0.0038705"
        iyz="0.0032"
        izz="0.007672" />
    </inertial>
    <visual>
      <origin
        xyz="0 0 0"
        rpy="0 0 0" />
      <geometry>
        <mesh
          filename="package://xarm_description/meshes/xarm7/visual/link2.STL" />
      </geometry>
      <material name="White" />
    </visual>
    <collision>
      <origin
        xyz="0 0 0"
        rpy="0 0 0" />
      <geometry>
        <mesh
          filename="package://xarm_description/meshes/xarm7/visual/link2.STL" />
      </geometry>
    </collision>
  </link>
  <joint
    name="${prefix}joint2"
    type="revolute">
    <origin
      xyz="0 0 0"
      rpy="-1.5708 0 0" />
    <parent
      link="${prefix}link1" />
    <child
      link="${prefix}link2" />
    <axis
      xyz="0 0 1" />
    <limit
      lower="${joint2_lower_limit}"
      upper="${joint2_upper_limit}"
      effort="50"
      velocity="3.14" />
    <dynamics
      damping="10"
      friction="1" />
  </joint>
  <link
    name="${prefix}link3">
    <inertial>
      <origin
        xyz="0.04676 -0.02526 -0.00746"
        rpy="0 0 0" />
      <mass
        value="1.6854" />
      <inertia
        ixx="0.0031588"
        ixy="-3.1443E-04"
        ixz="5.8658E-04"
        iyy="0.002682"
        iyz="-3.469E-04"
        izz="0.0027105" />
    </inertial>
    <visual>
      <origin
        xyz="0 0 0"
        rpy="0 0 0" />
      <geometry>
        <mesh
          filename="package://xarm_description/meshes/xarm7/visual/link3.STL" />
      </geometry>
      <material name="White" />
    </visual>
    <collision>
      <origin
        xyz="0 0 0"
        rpy="0 0 0" />
      <geometry>
        <mesh
          filename="package://xarm_description/meshes/xarm7/visual/link3.STL" />
      </geometry>
    </collision>
  </link>
  <joint
    name="${prefix}joint3"
    type="revolute">
    <origin
      xyz="0 -0.293 0"
      rpy="1.5708 0 0" />
    <parent
      link="${prefix}link2" />
    <child
      link="${prefix}link3" />
    <axis
      xyz="0 0 1" />
    <limit
      lower="${joint3_lower_limit}"
      upper="${joint3_upper_limit}"
      effort="30"
      velocity="3.14" />
    <dynamics
      damping="5"
      friction="1" />
  </joint>
  <link
    name="${prefix}link4">
    <inertial>
      <origin
        xyz="0.07066 -0.11664 0.0117"
        rpy="0 0 0" />
      <mass
        value="1.774" />
      <inertia
        ixx="0.005967"
        ixy="-0.001382"
        ixz="-0.00088544"
        iyy="0.00363897"
        iyz="0.0017806"
        izz="0.005509226" />
    </inertial>
    <visual>
      <origin
        xyz="0 0 0"
        rpy="0 0 0" />
      <geometry>
        <mesh
          filename="package://xarm_description/meshes/xarm7/visual/link4.STL" />
      </geometry>
      <material name="White" />
    </visual>
    <collision>
      <origin
        xyz="0 0 0"
        rpy="0 0 0" />
      <geometry>
        <mesh
          filename="package://xarm_description/meshes/xarm7/visual/link4.STL" />
      </geometry>
    </collision>
  </link>
  <joint
    name="${prefix}joint4"
    type="revolute">
    <origin
      xyz="0.0525 0 0"
      rpy="1.5708 0 0" />
    <parent
      link="${prefix}link3" />
    <child
      link="${prefix}link4" />
    <axis
      xyz="0 0 1" />
    <limit
      lower="${joint4_lower_limit}"
      upper="${joint4_upper_limit}"
      effort="30"
      velocity="3.14" />
    <dynamics
      damping="5"
      friction="1" />
  </joint>
  <link
    name="${prefix}link5">
    <inertial>
      <origin
        xyz="-0.00031 0.01558 -0.0253"
        rpy="0 0 0" />
      <mass
        value="1.357" />
      <inertia
        ixx="0.005396"
        ixy="-1.53E-05"
        ixz="-6.7E-07"
        iyy="0.005"
        iyz="0.00020544"
        izz="0.00138734" />
    </inertial>
    <visual>
      <origin
        xyz="0 0 0"
        rpy="0 0 0" />
      <geometry>
        <mesh
          filename="package://xarm_description/meshes/xarm7/visual/link5.STL" />
      </geometry>
      <material name="White" />
    </visual>
    <collision>
      <origin
        xyz="0 0 0"
        rpy="0 0 0" />
      <geometry>
        <mesh
          filename="package://xarm_description/meshes/xarm7/visual/link5.STL" />
      </geometry>
    </collision>
  </link>
  <joint
    name="${prefix}joint5"
    type="revolute">
    <origin
      xyz="0.0775 -0.3425 0"
      rpy="1.5708 0 0" />
    <parent
      link="${prefix}link4" />
    <child
      link="${prefix}link5" />
    <axis
      xyz="0 0 1" />
    <limit
      lower="${joint5_lower_limit}"
      upper="${joint5_upper_limit}"
      effort="30"
      velocity="3.14" />
    <dynamics
      damping="5"
      friction="1" />
  </joint>
  <link
    name="${prefix}link6">
    <inertial>
      <origin
        xyz="0.065 0.03336 0.02131"
        rpy="0 0 0" />
      <mass
        value="1.362" />
      <inertia
        ixx="0.0015057"
        ixy="0.000496735"
        ixz="-2.9968E-04"
        iyy="0.0019297"
        iyz="-1.5E-04"
        izz="0.0024" />
    </inertial>
    <visual>
      <origin
        xyz="0 0 0"
        rpy="0 0 0" />
      <geometry>
        <mesh
          filename="package://xarm_description/meshes/xarm7/visual/link6.STL" />
      </geometry>
      <material name="White" />
    </visual>
    <collision>
      <origin
        xyz="0 0 0"
        rpy="0 0 0" />
      <geometry>
        <mesh
          filename="package://xarm_description/meshes/xarm7/visual/link6.STL" />
      </geometry>
    </collision>
  </link>
  <joint
    name="${prefix}joint6"
    type="revolute">
    <origin
      xyz="0 0 0"
      rpy="1.5708 0 0" />
    <parent
      link="${prefix}link5" />
    <child
      link="${prefix}link6" />
    <axis
      xyz="0 0 1" />
    <limit
      lower="${joint6_lower_limit}"
      upper="${joint6_upper_limit}"
      effort="20"
      velocity="3.14" />
    <dynamics
      damping="2"
      friction="1" />
  </joint>
  <link
    name="${prefix}link7">
    <inertial>
      <origin
        xyz="0 -0.00677 -0.01098"
        rpy="0 0 0" />
      <mass
        value="0.17" />
      <inertia
        ixx="9.3E-05"
        ixy="0.0"
        ixz="0.0"
        iyy="5.87E-05"
        iyz="3.6E-06"
        izz="1.32E-04" />
    </inertial>
    <visual>
      <origin
        xyz="0 0 0"
        rpy="0 0 0" />
      <geometry>
        <xacro:if value="${model1300}">
          <mesh filename="package://xarm_description/meshes/end_tool/visual/end_tool_1300.STL" />
        </xacro:if>
        <xacro:unless value="${model1300}">
          <mesh filename="package://xarm_description/meshes/xarm7/visual/link7.STL" />
        </xacro:unless>
      </geometry>
      <material name="Silver" />
    </visual>
    <collision>
      <origin
        xyz="0 0 0"
        rpy="0 0 0" />
      <geometry>
        <xacro:if value="${model1300}">
          <mesh filename="package://xarm_description/meshes/end_tool/collision/end_tool_1300.STL" />
        </xacro:if>
        <xacro:unless value="${model1300}">
          <mesh filename="package://xarm_description/meshes/end_tool/collision/end_tool.STL" />
        </xacro:unless>
      </geometry>
    </collision>
  </link>
  <joint
    name="${prefix}joint7"
    type="revolute">
    <origin
      xyz="0.076 0.097 0"
      rpy="-1.5708 0 0" />
    <parent
      link="${prefix}link6" />
    <child
      link="${prefix}link7" />
    <axis
      xyz="0 0 1" />
    <limit
      lower="${joint7_lower_limit}"
      upper="${joint7_upper_limit}"
      effort="20"
      velocity="3.14" />
    <dynamics
      damping="2"
      friction="1" />
  </joint>

  <xacro:if value="${rs_d435i}">
    <link name="${prefix}link_eef">
      <visual>
        <origin
          xyz="0 0 0"
          rpy="0 0 0" />
        <geometry>
          <mesh
            filename="package://d435i_xarm_setup/mesh/d435_with_cam_stand.STL" />
        </geometry>
        <material name="Silver" />
      </visual>
      <collision>
        <origin
          xyz="0 0 0"
          rpy="0 0 0" />
        <geometry>
          <mesh
            filename="package://d435i_xarm_setup/mesh/d435_with_cam_stand_collision.STL" />
        </geometry>
      </collision>
    </link>
  </xacro:if>

  <xacro:unless value="${rs_d435i}">
    <link name="${prefix}link_eef"/>
  </xacro:unless>

  <joint
    name="${prefix}joint_eef"
    type="fixed">
    <origin
      xyz="0 0 0"
      rpy="0 0 0" />
    <parent
      link="${prefix}link7" />
    <child
      link="${prefix}link_eef" />
  </joint>
  
  </xacro:macro>
</robot>