<?xml version="1.0"?>
<robot xmlns:xacro="http://ros.org/wiki/xacro">
  <xacro:macro name="lite6_urdf" params="prefix
    joint1_lower_limit:=${-2.0*pi}  joint1_upper_limit:=${2.0*pi}
    joint2_lower_limit:=${-2.61799}  joint2_upper_limit:=${2.61799}
    joint3_lower_limit:=${-0.061087}  joint3_upper_limit:=${5.235988}
    joint4_lower_limit:=${-2.0*pi}  joint4_upper_limit:=${2.0*pi}
    joint5_lower_limit:=${-2.1642}  joint5_upper_limit:=${2.1642}
    joint6_lower_limit:=${-2.0*pi}  joint6_upper_limit:=${2.0*pi}
    model_num:=0
    inertial_params_filename:='' kinematics_params_filename:='' "
    >

    <!-- load params and define property -->
    <xacro:property name="default_inertial_params_filename" value="xarm6_type9_HT_BR2"/>
    <xacro:if value="${inertial_params_filename != ''}">
      <xacro:property name="link_inertial_params_file" value="$(find xarm_description)/config/link_inertial/${inertial_params_filename}.yaml"/>
    </xacro:if>
    <xacro:unless value="${inertial_params_filename != ''}">
      <xacro:property name="link_inertial_params_file" value="$(find xarm_description)/config/link_inertial/${default_inertial_params_filename}.yaml"/>
    </xacro:unless>
    <xacro:if value="${use_xacro_load_yaml}">
      <xacro:property name="inertial_params" value="${xacro.load_yaml(link_inertial_params_file)}"/>
      <xacro:property name="kinematics_config" value="${xacro.load_yaml(kinematics_params_filename)}"/>
    </xacro:if>
    <xacro:unless value="${use_xacro_load_yaml}">
      <xacro:property name="inertial_params" value="${load_yaml(link_inertial_params_file)}"/>
      <xacro:property name="kinematics_config" value="${load_yaml(kinematics_params_filename)}"/>
    </xacro:unless>
    <xacro:property name="kinematics_params" value="${kinematics_config['kinematics']}"/>
    
    <link name="${prefix}link_base">
      <inertial>
        <origin xyz="-0.00829544579053192 3.26357432323433E-05 0.0631194584987089" rpy="0 0 0" />
        <mass value="1.65393501783165" />
        <inertia
          ixx="0" ixy="0" ixz="0"
          iyy="0" iyz="0" izz="0" />
      </inertial>
      <xacro:common_link_visual 
        mesh_filename="lite6/visual/link_base"  
        origin_xyz="0 0 0" 
        origin_rpy="0 0 0"
        material_name="${prefix}White" />
      <xacro:common_link_collision 
        mesh_filename="lite6/collision/link_base"  
        origin_xyz="0 0 0" 
        origin_rpy="0 0 0" />
    </link>
    <link name="${prefix}link1">
      <xacro:common_link_inertial 
        link_inertial_params="${inertial_params['link1']}" 
        origin_rpy="0 0 0"/>
      <xacro:common_link_visual 
        mesh_filename="lite6/visual/link1"  
        origin_xyz="0 0 0" 
        origin_rpy="0 0 0"
        material_name="${prefix}White" />
      <xacro:common_link_collision 
        mesh_filename="lite6/collision/link1"  
        origin_xyz="0 0 0" 
        origin_rpy="0 0 0" />
    </link>
    <joint name="${prefix}joint1" type="revolute">
      <!-- <origin xyz="0 0 0.2435" rpy="0 0 0" /> -->
      <xacro:common_joint_origin joint_kinematic_params="${kinematics_params['joint1']}" />
      <parent link="${prefix}link_base" />
      <child link="${prefix}link1" />
      <axis xyz="0 0 1" />
      <limit
        lower="${joint1_lower_limit}"
        upper="${joint1_upper_limit}"
        effort="50.0"
        velocity="3.14"/>
      <dynamics damping="1.0" friction="1.0"/>
    </joint>
    <link name="${prefix}link2">
      <xacro:common_link_inertial 
        link_inertial_params="${inertial_params['link2']}" 
        origin_rpy="0 0 0"/>
      <xacro:common_link_visual 
        mesh_filename="lite6/visual/link2"  
        origin_xyz="0 0 ${-kinematics_params['joint2']['y']}" 
        origin_rpy="0 0 0"
        material_name="${prefix}White" />
      <xacro:common_link_collision 
        mesh_filename="lite6/collision/link2"  
        origin_xyz="0 0 ${-kinematics_params['joint2']['y']}" 
        origin_rpy="0 0 0" />
    </link>
    <joint name="${prefix}joint2" type="revolute">
      <!-- <origin xyz="0 0 0" rpy="1.5708 -1.5708 3.1416" /> -->
      <xacro:common_joint_origin joint_kinematic_params="${kinematics_params['joint2']}" />
      <parent link="${prefix}link1" />
      <child link="${prefix}link2" />
      <axis xyz="0 0 1" />
      <limit
        lower="${joint2_lower_limit}"
        upper="${joint2_upper_limit}"
        effort="50.0"
        velocity="3.14"/>
      <dynamics damping="1.0" friction="1.0"/>
    </joint>
    <link name="${prefix}link3">
      <xacro:common_link_inertial 
        link_inertial_params="${inertial_params['link3']}" 
        origin_rpy="0 0 0"/>
      <xacro:common_link_visual 
        mesh_filename="lite6/visual/link3"  
        origin_xyz="0 0 0" 
        origin_rpy="0 0 0"
        material_name="${prefix}White" />
      <xacro:common_link_collision 
        mesh_filename="lite6/collision/link3"  
        origin_xyz="0 0 0" 
        origin_rpy="0 0 0" />
    </link>
    <joint name="${prefix}joint3" type="revolute">
      <!-- <origin xyz="0.2002 0 0" rpy="-3.1416 0 1.5708" /> -->
      <xacro:common_joint_origin joint_kinematic_params="${kinematics_params['joint3']}" />
      <parent link="${prefix}link2" />
      <child link="${prefix}link3" />
      <axis xyz="0 0 1" />
      <limit
        lower="${joint3_lower_limit}"
        upper="${joint3_upper_limit}"
        effort="32.0"
        velocity="3.14"/>
      <dynamics damping="1.0" friction="1.0"/>
    </joint>
    <link name="${prefix}link4">
      <xacro:common_link_inertial 
        link_inertial_params="${inertial_params['link4']}" 
        origin_rpy="0 0 0"/>
      <xacro:common_link_visual 
        mesh_filename="lite6/visual/link4"  
        origin_xyz="0 0 0" 
        origin_rpy="0 0 0"
        material_name="${prefix}White" />
      <xacro:common_link_collision 
        mesh_filename="lite6/collision/link4"  
        origin_xyz="0 0 0" 
        origin_rpy="0 0 0" />
    </link>
    <joint name="${prefix}joint4" type="revolute">
      <!-- <origin xyz="0.087 -0.22761 0" rpy="1.5708 0 0" /> -->
      <xacro:common_joint_origin joint_kinematic_params="${kinematics_params['joint4']}" />
      <parent link="${prefix}link3" />
      <child link="${prefix}link4" />
      <axis xyz="0 0 1" />
      <limit
        lower="${joint4_lower_limit}"
        upper="${joint4_upper_limit}"
        effort="32.0"
        velocity="3.14"/>
      <dynamics damping="1.0" friction="1.0"/>
    </joint>
    <link name="${prefix}link5">
      <xacro:common_link_inertial 
        link_inertial_params="${inertial_params['link5']}" 
        origin_rpy="0 0 0"/>
      <xacro:common_link_visual 
        mesh_filename="lite6/visual/link5"  
        origin_xyz="0 0 0" 
        origin_rpy="0 0 0"
        material_name="${prefix}White" />
      <xacro:common_link_collision 
        mesh_filename="lite6/collision/link5"  
        origin_xyz="0 0 0" 
        origin_rpy="0 0 0" />
    </link>
    <joint name="${prefix}joint5" type="revolute">
      <!-- <origin xyz="0 0 0" rpy="1.5708 0 0" /> -->
      <xacro:common_joint_origin joint_kinematic_params="${kinematics_params['joint5']}" />
      <parent link="${prefix}link4" />
      <child link="${prefix}link5" />
      <axis xyz="0 0 1" />
      <limit
        lower="${joint5_lower_limit}"
        upper="${joint5_upper_limit}"
        effort="32.0"
        velocity="3.14"/>
      <dynamics damping="1.0" friction="1.0"/>
    </joint>
    <link name="${prefix}link6">
      <xacro:common_link_inertial 
        link_inertial_params="${inertial_params['link6']}" 
        origin_rpy="0 0 0"/>
      <xacro:common_link_visual 
        mesh_filename="lite6/visual/link6"  
        origin_xyz="0 0 0" 
        origin_rpy="0 0 0"
        material_name="${prefix}Silver" />
      <xacro:common_link_collision 
        mesh_filename="lite6/collision/link6"  
        origin_xyz="0 0 0" 
        origin_rpy="0 0 0" />
    </link>
    <joint name="${prefix}joint6" type="revolute">
      <!-- <origin xyz="0 0.0625 0" rpy="-1.5708 0 0" /> -->
      <xacro:common_joint_origin joint_kinematic_params="${kinematics_params['joint6']}" />
      <parent link="${prefix}link5" />
      <child link="${prefix}link6" />
      <axis xyz="0 0 1" />
      <limit
        lower="${joint6_lower_limit}"
        upper="${joint6_upper_limit}"
        effort="20.0"
        velocity="3.14"/>
      <dynamics damping="1.0" friction="1.0"/>
    </joint>

    <!-- <link name="${prefix}link_eef" />
    <joint name="${prefix}joint_eef" type="fixed">
      <origin xyz="0 0 0" rpy="0 0 0" />
      <parent link="${prefix}link6" />
      <child link="${prefix}link_eef" />
    </joint> -->
  </xacro:macro>
</robot>