<?xml version="1.0"?>
<robot xmlns:xacro="http://ros.org/wiki/xacro">

  <xacro:macro name="xarm7_mirror_urdf" params="prefix
    joint1_lower_limit:=${-2.0*pi}  joint1_upper_limit:=${2.0*pi}
    joint2_lower_limit:=${-2.0944}  joint2_upper_limit:=${2.059}
    joint3_lower_limit:=${-2.0*pi}  joint3_upper_limit:=${2.0*pi}
    joint4_lower_limit:=${-3.927}   joint4_upper_limit:=${0.19198}
    joint5_lower_limit:=${-2.0*pi}  joint5_upper_limit:=${2.0*pi}
    joint6_lower_limit:=${-pi}      joint6_upper_limit:=${1.69297}
    joint7_lower_limit:=${-2.0*pi}  joint7_upper_limit:=${2.0*pi}
    model_num:=0
    inertial_params_filename:='' kinematics_params_filename:='' "
    >

    <!-- load params and define property -->
    <xacro:property name="default_inertial_params_filename" value="xarm7_type13_HT_BR2"/>
    <xacro:if value="${inertial_params_filename != ''}">
      <xacro:property name="link_inertial_params_file" value="$(find xarm_description)/config/link_inertial/${inertial_params_filename}.yaml"/>
    </xacro:if>
    <xacro:unless value="${inertial_params_filename != ''}">
      <xacro:property name="link_inertial_params_file" value="$(find xarm_description)/config/link_inertial/${default_inertial_params_filename}.yaml"/>
    </xacro:unless>
    <xacro:if value="${use_xacro_load_yaml}">
      <xacro:property name="inertial_params" value="${xacro.load_yaml(link_inertial_params_file)}"/>
      <xacro:property name="kinematics_config" value="${xacro.load_yaml(kinematics_params_filename)}"/>
    </xacro:if>
    <xacro:unless value="${use_xacro_load_yaml}">
      <xacro:property name="inertial_params" value="${load_yaml(link_inertial_params_file)}"/>
      <xacro:property name="kinematics_config" value="${load_yaml(kinematics_params_filename)}"/>
    </xacro:unless>
    <xacro:property name="kinematics_params" value="${kinematics_config['kinematics']}"/>

    <link name="${prefix}link_base">
      <inertial>
        <origin xyz="-0.00135 -1.3E-04 0.0965" rpy="0 0 0" />
        <mass value="2.53" />
        <inertia
          ixx="0.00639" ixy="2.2E-05" ixz="-0.000241"
          iyy="0.006538" iyz="7.0E-06" izz="0.003129" />
      </inertial>
      <xacro:common_link_visual 
        mesh_filename="xarm7_mirror/visual/link_base"  
        origin_xyz="0 0 0" 
        origin_rpy="0 0 0"
        material_name="${prefix}White" />
      <xacro:common_link_collision 
        mesh_filename="xarm7_mirror/collision/link_base"  
        origin_xyz="0 0 0" 
        origin_rpy="0 0 0" />
    </link>
    <link name="${prefix}link1">
      <xacro:common_link_inertial 
        link_inertial_params="${inertial_params['link1']}" 
        origin_rpy="0 0 0"/>
      <xacro:common_link_visual 
        mesh_filename="xarm7_mirror/visual/link1"  
        origin_xyz="0 0 0" 
        origin_rpy="0 0 0"
        material_name="${prefix}White" />
      <xacro:common_link_collision 
        mesh_filename="xarm7_mirror/collision/link1"  
        origin_xyz="0 0 0" 
        origin_rpy="0 0 0" />
    </link>
    <joint name="${prefix}joint1" type="revolute">
      <xacro:common_joint_origin joint_kinematic_params="${kinematics_params['joint1']}" />
      <parent link="${prefix}link_base" />
      <child link="${prefix}link1" />
      <axis xyz="0 0 1" />
      <limit
        lower="${joint1_lower_limit}"
        upper="${joint1_upper_limit}"
        effort="50"
        velocity="3.14" />
      <dynamics damping="10" friction="1" />
    </joint>
    <link name="${prefix}link2">
      <xacro:common_link_inertial 
        link_inertial_params="${inertial_params['link2']}" 
        origin_rpy="0 0 0"/>
      <xacro:common_link_visual 
        mesh_filename="xarm7_mirror/visual/link2"  
        origin_xyz="0 0 0" 
        origin_rpy="0 0 0"
        material_name="${prefix}White" />
      <xacro:common_link_collision 
        mesh_filename="xarm7_mirror/collision/link2"  
        origin_xyz="0 0 0" 
        origin_rpy="0 0 0" />
    </link>
    <joint name="${prefix}joint2" type="revolute">
      <xacro:common_joint_origin joint_kinematic_params="${kinematics_params['joint2']}" />
      <parent link="${prefix}link1" />
      <child link="${prefix}link2" />
      <axis xyz="0 0 1" />
      <limit
        lower="${joint2_lower_limit}"
        upper="${joint2_upper_limit}"
        effort="50"
        velocity="3.14" />
      <dynamics damping="10" friction="1" />
    </joint>
    <link name="${prefix}link3">
      <xacro:common_link_inertial 
        link_inertial_params="${inertial_params['link3']}" 
        origin_rpy="0 0 0"/>
      <xacro:common_link_visual 
        mesh_filename="xarm7_mirror/visual/link3"  
        origin_xyz="0 0 0" 
        origin_rpy="0 0 0"
        material_name="${prefix}White" />
      <xacro:common_link_collision 
        mesh_filename="xarm7_mirror/collision/link3"  
        origin_xyz="0 0 0" 
        origin_rpy="0 0 0" />
    </link>
    <joint name="${prefix}joint3" type="revolute">
      <xacro:common_joint_origin joint_kinematic_params="${kinematics_params['joint3']}" />
      <parent link="${prefix}link2" />
      <child link="${prefix}link3" />
      <axis xyz="0 0 1" />
      <limit
        lower="${joint3_lower_limit}"
        upper="${joint3_upper_limit}"
        effort="30"
        velocity="3.14" />
      <dynamics damping="5" friction="1" />
    </joint>
    <link name="${prefix}link4">
      <xacro:common_link_inertial 
        link_inertial_params="${inertial_params['link4']}" 
        origin_rpy="0 0 0"/>
      <xacro:common_link_visual 
        mesh_filename="xarm7_mirror/visual/link4"  
        origin_xyz="0 0 0" 
        origin_rpy="0 0 0"
        material_name="${prefix}White" />
      <xacro:common_link_collision 
        mesh_filename="xarm7_mirror/collision/link4"  
        origin_xyz="0 0 0" 
        origin_rpy="0 0 0" />
    </link>
    <joint name="${prefix}joint4" type="revolute">
      <xacro:common_joint_origin joint_kinematic_params="${kinematics_params['joint4']}" />
      <parent link="${prefix}link3" />
      <child link="${prefix}link4" />
      <axis xyz="0 0 1" />
      <limit
        lower="${joint4_lower_limit}"
        upper="${joint4_upper_limit}"
        effort="30"
        velocity="3.14" />
      <dynamics damping="5" friction="1" />
    </joint>
    <link name="${prefix}link5">
      <xacro:common_link_inertial 
        link_inertial_params="${inertial_params['link5']}" 
        origin_rpy="0 0 0"/>
      <xacro:common_link_visual 
        mesh_filename="xarm7_mirror/visual/link5"  
        origin_xyz="0 0 0" 
        origin_rpy="0 0 0"
        material_name="${prefix}White" />
      <xacro:common_link_collision 
        mesh_filename="xarm7_mirror/collision/link5"  
        origin_xyz="0 0 0" 
        origin_rpy="0 0 0" />
    </link>
    <joint name="${prefix}joint5" type="revolute">
      <xacro:common_joint_origin joint_kinematic_params="${kinematics_params['joint5']}" />
      <parent link="${prefix}link4" />
      <child link="${prefix}link5" />
      <axis xyz="0 0 1" />
      <limit
        lower="${joint5_lower_limit}"
        upper="${joint5_upper_limit}"
        effort="30"
        velocity="3.14" />
      <dynamics damping="5" friction="1" />
    </joint>
    <link name="${prefix}link6">
      <xacro:common_link_inertial 
        link_inertial_params="${inertial_params['link6']}" 
        origin_rpy="0 0 0"/>
      <xacro:common_link_visual 
        mesh_filename="xarm7_mirror/visual/link6"  
        origin_xyz="0 0 0" 
        origin_rpy="0 0 0"
        material_name="${prefix}White" />
      <xacro:common_link_collision 
        mesh_filename="xarm7_mirror/collision/link6"  
        origin_xyz="0 0 0" 
        origin_rpy="0 0 0" />
    </link>
    <joint name="${prefix}joint6" type="revolute">
      <xacro:common_joint_origin joint_kinematic_params="${kinematics_params['joint6']}" />
      <parent link="${prefix}link5" />
      <child link="${prefix}link6" />
      <axis xyz="0 0 1" />
      <limit
        lower="${joint6_lower_limit}"
        upper="${joint6_upper_limit}"
        effort="20"
        velocity="3.14" />
      <dynamics damping="2" friction="1" />
    </joint>
    <link name="${prefix}link7">
      <xacro:common_link_inertial 
        link_inertial_params="${inertial_params['link7']}" 
        origin_rpy="0 0 0"/>
      <xacro:common_link_visual 
        mesh_filename="xarm7_mirror/visual/link7"  
        origin_xyz="0 0 0" 
        origin_rpy="0 0 0"
        material_name="${prefix}White" />
      <xacro:common_link_collision 
        mesh_filename="xarm7_mirror/collision/link7"  
        origin_xyz="0 0 0" 
        origin_rpy="0 0 0" />
    </link>
    <joint name="${prefix}joint7" type="revolute">
      <xacro:common_joint_origin joint_kinematic_params="${kinematics_params['joint7']}" />
      <parent link="${prefix}link6" />
      <child link="${prefix}link7" />
      <axis xyz="0 0 1" />
      <limit
        lower="${joint7_lower_limit}"
        upper="${joint7_upper_limit}"
        effort="20"
        velocity="3.14" />
      <dynamics damping="2" friction="1" />
    </joint>

    <!-- <link name="${prefix}link_eef" />
    <joint name="${prefix}joint_eef" type="fixed">
      <origin xyz="0 0 0" rpy="0 0 0" />
      <parent link="${prefix}link7" />
      <child link="${prefix}link_eef" />
    </joint> -->
  
  </xacro:macro>
</robot>